/usr/bin/python: can't open file '/opt/NeMo-Aligner/examples/nlp/data/steerlm/preprocess_openassistant.py': [Errno 2] No such file or directory
[2024-01-12 13:53:23,846] torch.distributed.elastic.multiprocessing.api: [ERROR] failed (exitcode: 2) local_rank: 0 (pid: 163072) of binary: /usr/bin/python
Traceback (most recent call last):
  File "/usr/local/bin/torchrun", line 8, in <module>
    sys.exit(main())
  File "/usr/local/lib/python3.10/dist-packages/torch/distributed/elastic/multiprocessing/errors/__init__.py", line 346, in wrapper
    return f(*args, **kwargs)
  File "/usr/local/lib/python3.10/dist-packages/torch/distributed/run.py", line 806, in main
    run(args)
  File "/usr/local/lib/python3.10/dist-packages/torch/distributed/run.py", line 797, in run
    elastic_launch(
  File "/usr/local/lib/python3.10/dist-packages/torch/distributed/launcher/api.py", line 134, in __call__
    return launch_agent(self._config, self._entrypoint, list(args))
  File "/usr/local/lib/python3.10/dist-packages/torch/distributed/launcher/api.py", line 264, in launch_agent
    raise ChildFailedError(
torch.distributed.elastic.multiprocessing.errors.ChildFailedError: 
============================================================
/opt/NeMo-Aligner/examples/nlp/data/steerlm/preprocess_openassistant.py FAILED
------------------------------------------------------------
Failures:
  <NO_OTHER_FAILURES>
------------------------------------------------------------
Root Cause (first observed failure):
[0]:
  time      : 2024-01-12_13:53:23
  host      : bumblebee
  rank      : 0 (local_rank: 0)
  exitcode  : 2 (pid: 163072)
  error_file: <N/A>
  traceback : To enable traceback see: https://pytorch.org/docs/stable/elastic/errors.html
============================================================
